<mujoco model="ur5e_shadow_hand">
  <compiler angle="radian" assetdir="assets" autolimits="true" />

  <option impratio="10" />

  <default>
    <joint axis="0 1 0" range="-6.28319 6.28319" />
    <position ctrlrange="-6.2831 6.2831" />

    <default class="visual">
      <geom type="mesh" contype="0" conaffinity="0" group="2" />
    </default>
    <default class="collision">
      <geom type="capsule" group="3" />
      <default class="eef_collision">
        <geom type="cylinder" />
      </default>
    </default>
    <site size="0.001" rgba="0.5 0.5 0.5 0.3" group="4" />

    <!-- Reference:
      https://www.universal-robots.com/articles/ur/robot-care-maintenance/max-joint-torques/ -->
    <default class="size3">
      <joint armature="0.1" damping="200" />
      <position kp="3500" forcerange="-150 150" />
      <default class="size3_limited">
        <joint range="-3.1415 3.1415" />
        <position ctrlrange="-3.1415 3.1415" />
      </default>
    </default>
    <default class="size1">
      <joint armature="0.1" damping="15" />
      <position kp="3000" forcerange="-28 28" />
    </default>

    <!-- Shadow Hand -->
    <default class="right_hand">
      <mesh scale="0.001 0.001 0.001" />
      <joint axis="1 0 0" damping="0.05" armature="0.0002" frictionloss="0.01" />
      <position forcerange="-1 1" />

      <default class="wrist">
        <joint damping="0.5" />
        <default class="wrist_y">
          <joint axis="0 1 0" range="-0.523599 0.174533" />
          <position kp="10" ctrlrange="-0.523599 0.174533" forcerange="-10 10" />
        </default>
        <default class="wrist_x">
          <joint range="-0.698132 0.488692" />
          <position kp="8" ctrlrange="-0.698132 0.488692" forcerange="-5 5" />
        </default>
      </default>

      <default class="thumb">
        <default class="thbase">
          <joint axis="0 0 -1" range="-1.0472 1.0472" />
          <position kp="0.4" ctrlrange="-1.0472 1.0472" forcerange="-3 3" />
        </default>
        <default class="thproximal">
          <joint range="0 1.22173" />
          <position ctrlrange="0 1.22173" forcerange="-2 2" />
        </default>
        <default class="thhub">
          <joint range="-0.20944 0.20944" />
          <position kp="0.5" ctrlrange="-0.20944 0.20944" />
        </default>
        <default class="thmiddle">
          <joint axis="0 -1 0" range="-0.698132 0.698132" />
          <position kp="1.5" ctrlrange="-0.698132 0.698132" />
        </default>
        <default class="thdistal">
          <joint range="-0.261799 1.5708" />
          <position ctrlrange="-0.261799 1.5708" />
        </default>
      </default>

      <default class="metacarpal">
        <joint axis="0.573576 0 0.819152" range="0 0.785398" />
        <position ctrlrange="0 0.785398" />
      </default>
      <default class="knuckle">
        <joint axis="0 -1 0" range="-0.349066 0.349066" />
        <position ctrlrange="-0.349066 0.349066" />
      </default>
      <default class="proximal">
        <joint range="-0.261799 1.5708" />
        <position ctrlrange="-0.261799 1.5708" />
      </default>
      <default class="middle_distal">
        <joint range="0 1.5708" />
        <position kp="0.5" ctrlrange="0 3.1415" />
      </default>

      <default class="plastic">
        <geom solimp="0.5 0.99 0.0001" solref="0.005 1" />
        <default class="plastic_visual">
          <geom type="mesh" material="black" contype="0" conaffinity="0" group="2" />
        </default>
        <default class="plastic_collision">
          <geom group="3" />
        </default>
      </default>
    </default>
  </default>

  <asset>
    <material name="matteblack" specular="0.5" shininess="0.25" rgba="0.033 0.033 0.033 1" />
    <material name="jointgray" specular="0.5" shininess="0.25" rgba="0.278 0.278 0.278 1" />
    <material name="linkgray" specular="0.5" shininess="0.25" rgba="0.82 0.82 0.82 1" />
    <material name="urblue" specular="0.5" shininess="0.25" rgba="0.49 0.678 0.8 1" />

    <mesh file="base_0.obj" />
    <mesh file="base_1.obj" />
    <mesh file="shoulder_0.obj" />
    <mesh file="shoulder_1.obj" />
    <mesh file="shoulder_2.obj" />
    <mesh file="upperarm_0.obj" />
    <mesh file="upperarm_1.obj" />
    <mesh file="upperarm_2.obj" />
    <mesh file="upperarm_3.obj" />
    <mesh file="forearm_0.obj" />
    <mesh file="forearm_1.obj" />
    <mesh file="forearm_2.obj" />
    <mesh file="forearm_3.obj" />
    <mesh file="wrist1_0.obj" />
    <mesh file="wrist1_1.obj" />
    <mesh file="wrist1_2.obj" />
    <mesh file="wrist2_0.obj" />
    <mesh file="wrist2_1.obj" />
    <mesh file="wrist2_2.obj" />
    <mesh file="wrist3.obj" />

    <!-- Shadow Hand -->
    <material name="black" specular="0.5" shininess="0.25" rgba="0.16355 0.16355 0.16355 1" />
    <material name="gray" specular="0.0" shininess="0.25" rgba="0.80848 0.80848 0.80848 1" />
    <material name="metallic" specular="0" shininess="0.25" rgba="0.9 0.9 0.9 1" />

    <mesh class="right_hand" file="shadow_forearm_0.obj" />
    <mesh class="right_hand" file="shadow_forearm_1.obj" />
    <mesh class="right_hand" file="shadow_forearm_collision.obj" />
    <mesh class="right_hand" file="wrist.obj" />
    <mesh class="right_hand" file="palm.obj" />
    <mesh class="right_hand" file="f_knuckle.obj" />
    <mesh class="right_hand" file="f_proximal.obj" />
    <mesh class="right_hand" file="f_middle.obj" />
    <mesh class="right_hand" file="f_distal_pst.obj" />
    <mesh class="right_hand" file="lf_metacarpal.obj" />
    <mesh class="right_hand" file="th_proximal.obj" />
    <mesh class="right_hand" file="th_middle.obj" />
    <mesh class="right_hand" file="th_distal_pst.obj" />
  </asset>

  <worldbody>
    <light name="spotlight" mode="targetbodycom" target="wrist_2_link" pos="0 -1 2" />
    <body name="base" quat="1 0 0 1">
      <inertial mass="4.0" pos="0 0 0" diaginertia="0.00443333156 0.00443333156 0.0072" />
      <geom mesh="base_0" material="matteblack" class="visual" />
      <geom mesh="base_1" material="jointgray" class="visual" />
      <body name="shoulder_link" pos="0 0 0.163">
        <inertial mass="3.7" pos="0 0 0" diaginertia="0.0102675 0.0102675 0.00666" />
        <joint name="shoulder_pan_joint" class="size3" axis="0 0 1" />
        <geom mesh="shoulder_0" material="urblue" class="visual" />
        <geom mesh="shoulder_1" material="matteblack" class="visual" />
        <geom mesh="shoulder_2" material="jointgray" class="visual" />
        <geom class="collision" size="0.06 0.06" pos="0 0 -0.04" />
        <body name="upper_arm_link" pos="0 0.138 0" quat="1 0 1 0">
          <inertial mass="8.393" pos="0 0 0.2125" diaginertia="0.133886 0.133886 0.0151074" />
          <joint name="shoulder_lift_joint" class="size3" />
          <geom mesh="upperarm_0" material="linkgray" class="visual" />
          <geom mesh="upperarm_1" material="matteblack" class="visual" />
          <geom mesh="upperarm_2" material="jointgray" class="visual" />
          <geom mesh="upperarm_3" material="urblue" class="visual" />
          <geom class="collision" pos="0 -0.04 0" quat="1 1 0 0" size="0.06 0.06" />
          <geom class="collision" size="0.05 0.2" pos="0 0 0.2" />
          <body name="forearm_link" pos="0 -0.131 0.425">
            <inertial mass="2.275" pos="0 0 0.196" diaginertia="0.0311796 0.0311796 0.004095" />
            <joint name="elbow_joint" class="size3_limited" />
            <geom mesh="forearm_0" material="urblue" class="visual" />
            <geom mesh="forearm_1" material="linkgray" class="visual" />
            <geom mesh="forearm_2" material="matteblack" class="visual" />
            <geom mesh="forearm_3" material="jointgray" class="visual" />
            <geom class="collision" pos="0 0.08 0" quat="1 1 0 0" size="0.055 0.06" />
            <geom class="collision" size="0.038 0.19" pos="0 0 0.2" />
            <body name="wrist_1_link" pos="0 0 0.392" quat="1 0 1 0">
              <inertial mass="1.219" pos="0 0.127 0" diaginertia="0.0025599 0.0025599 0.0021942" />
              <joint name="wrist_1_joint" class="size1" />
              <geom mesh="wrist1_0" material="matteblack" class="visual" />
              <geom mesh="wrist1_1" material="urblue" class="visual" />
              <geom mesh="wrist1_2" material="jointgray" class="visual" />
              <geom class="collision" pos="0 0.05 0" quat="1 1 0 0" size="0.04 0.07" />
              <body name="wrist_2_link" pos="0 0.127 0">
                <inertial mass="1.219" pos="0 0 0.1" diaginertia="0.0025599 0.0025599 0.0021942" />
                <joint name="wrist_2_joint" axis="0 0 1" class="size1" />
                <geom mesh="wrist2_0" material="matteblack" class="visual" />
                <geom mesh="wrist2_1" material="urblue" class="visual" />
                <geom mesh="wrist2_2" material="jointgray" class="visual" />
                <geom class="collision" size="0.04 0.06" pos="0 0 0.04" />
                <geom class="collision" pos="0 0.02 0.1" quat="1 1 0 0" size="0.04 0.04" />
                <body name="wrist_3_link" pos="0 0 0.1">
                  <inertial mass="0.1889" pos="0 0.0771683 0" quat="1 0 0 1"
                    diaginertia="0.000132134 9.90863e-05 9.90863e-05" />
                  <joint name="wrist_3_joint" class="size1" />
                  <geom material="linkgray" mesh="wrist3" class="visual" />
                  <geom class="eef_collision" pos="0 0.08 0" quat="1 1 0 0" size="0.04 0.02" />
                  <site name="attachment_site" pos="0 0.1 0" quat="-1 1 0 0" />

                  <!-- Shadow Hand -->
                  <body name="rh_forearm" childclass="right_hand" pos="0 0.09 0" euler="-1.570796 0 1.570796">
                    <inertial mass="3" pos="0 0 0.09" diaginertia="0.0138 0.0138 0.00744" />
                    <geom class="plastic_visual" mesh="shadow_forearm_0" material="gray" />
                    <geom class="plastic_visual" mesh="shadow_forearm_1" />
                    <geom class="plastic_collision" type="mesh" mesh="shadow_forearm_collision" />
                    <geom class="plastic_collision" size="0.035 0.035 0.035" pos="0 -0.01 0.181"
                      quat="0.924909 0 0.380188 0" type="box" />
                    <body name="rh_wrist" pos="0 -0.01 0.21301">
                      <inertial mass="0.1" pos="0 0 0.029" quat="0.5 0.5 0.5 0.5"
                        diaginertia="6.4e-05 4.38e-05 3.5e-05" />
                      <joint class="wrist_y" name="rh_WRJ2" />
                      <geom class="plastic_visual" mesh="wrist" material="metallic" />
                      <geom size="0.0135 0.015" quat="0.499998 0.5 0.5 -0.500002" type="cylinder"
                        class="plastic_collision" />
                      <geom size="0.011 0.005" pos="-0.026 0 0.034" quat="1 0 1 0" type="cylinder"
                        class="plastic_collision" />
                      <geom size="0.011 0.005" pos="0.031 0 0.034" quat="1 0 1 0" type="cylinder"
                        class="plastic_collision" />
                      <geom size="0.0135 0.009 0.005" pos="-0.021 0 0.011" quat="0.923879 0 0.382684 0" type="box"
                        class="plastic_collision" />
                      <geom size="0.0135 0.009 0.005" pos="0.026 0 0.01" quat="0.923879 0 -0.382684 0" type="box"
                        class="plastic_collision" />
                      <body name="rh_palm" pos="0 0 0.034">
                        <inertial mass="0.3" pos="0 0 0.035" quat="1 0 0 1"
                          diaginertia="0.0005287 0.0003581 0.000191" />
                        <joint class="wrist_x" name="rh_WRJ1" />
                        <site name="grasp_site" pos="0 -.035 0.09" group="4" />
                        <geom class="plastic_visual" mesh="palm" />
                        <geom size="0.031 0.0035 0.049" pos="0.011 0.0085 0.038" type="box"
                          class="plastic_collision" />
                        <geom size="0.018 0.0085 0.049" pos="-0.002 -0.0035 0.038" type="box"
                          class="plastic_collision" />
                        <geom size="0.013 0.0085 0.005" pos="0.029 -0.0035 0.082" type="box"
                          class="plastic_collision" />
                        <geom size="0.013 0.007 0.009" pos="0.0265 -0.001 0.07"
                          quat="0.987241 0.0990545 0.0124467 0.124052" type="box" class="plastic_collision" />
                        <geom size="0.0105 0.0135 0.012" pos="0.0315 -0.0085 0.001" type="box"
                          class="plastic_collision" />
                        <geom size="0.011 0.0025 0.015" pos="0.0125 -0.015 0.004" quat="0.971338 0 0 -0.237703"
                          type="box" class="plastic_collision" />
                        <geom size="0.009 0.012 0.002" pos="0.011 0 0.089" type="box" class="plastic_collision" />
                        <geom size="0.01 0.012 0.02" pos="-0.03 0 0.009" type="box" class="plastic_collision" />
                        <body name="rh_ffknuckle" pos="0.033 0 0.095">
                          <inertial mass="0.008" pos="0 0 0" quat="0.5 0.5 -0.5 0.5"
                            diaginertia="3.2e-07 2.6e-07 2.6e-07" />
                          <joint name="rh_FFJ4" class="knuckle" />
                          <geom pos="0 0 0.0005" class="plastic_visual" mesh="f_knuckle" material="metallic" />
                          <geom size="0.009 0.009" quat="1 0 1 0" type="cylinder" class="plastic_collision" />
                          <body name="rh_ffproximal">
                            <inertial mass="0.03" pos="0 0 0.0225" quat="1 0 0 1"
                              diaginertia="1e-05 9.8e-06 1.8e-06" />
                            <joint name="rh_FFJ3" class="proximal" />
                            <geom class="plastic_visual" mesh="f_proximal" />
                            <geom size="0.009 0.02" pos="0 0 0.025" type="capsule" class="plastic_collision" />
                            <body name="rh_ffmiddle" pos="0 0 0.045">
                              <inertial mass="0.017" pos="0 0 0.0125" quat="1 0 0 1"
                                diaginertia="2.7e-06 2.6e-06 8.7e-07" />
                              <joint name="rh_FFJ2" class="middle_distal" />
                              <geom class="plastic_visual" mesh="f_middle" />
                              <geom size="0.009 0.0125" pos="0 0 0.0125" type="capsule"
                                class="plastic_collision" />
                              <body name="rh_ffdistal" pos="0 0 0.025">
                                <inertial mass="0.013" pos="0 0 0.0130769" quat="1 0 0 1"
                                  diaginertia="1.28092e-06 1.12092e-06 5.3e-07" />
                                <joint name="rh_FFJ1" class="middle_distal" />
                                <geom class="plastic_visual" mesh="f_distal_pst" />
                                <geom class="plastic_collision" type="mesh" mesh="f_distal_pst" />
                              </body>
                            </body>
                          </body>
                        </body>
                        <body name="rh_mfknuckle" pos="0.011 0 0.099">
                          <inertial mass="0.008" pos="0 0 0" quat="0.5 0.5 -0.5 0.5"
                            diaginertia="3.2e-07 2.6e-07 2.6e-07" />
                          <joint name="rh_MFJ4" class="knuckle" />
                          <geom pos="0 0 0.0005" class="plastic_visual" mesh="f_knuckle" material="metallic" />
                          <geom size="0.009 0.009" quat="1 0 1 0" type="cylinder" class="plastic_collision" />
                          <body name="rh_mfproximal">
                            <inertial mass="0.03" pos="0 0 0.0225" quat="1 0 0 1"
                              diaginertia="1e-05 9.8e-06 1.8e-06" />
                            <joint name="rh_MFJ3" class="proximal" />
                            <geom class="plastic_visual" mesh="f_proximal" />
                            <geom size="0.009 0.02" pos="0 0 0.025" type="capsule" class="plastic_collision" />
                            <body name="rh_mfmiddle" pos="0 0 0.045">
                              <inertial mass="0.017" pos="0 0 0.0125" quat="1 0 0 1"
                                diaginertia="2.7e-06 2.6e-06 8.7e-07" />
                              <joint name="rh_MFJ2" class="middle_distal" />
                              <geom class="plastic_visual" mesh="f_middle" />
                              <geom size="0.009 0.0125" pos="0 0 0.0125" type="capsule"
                                class="plastic_collision" />
                              <body name="rh_mfdistal" pos="0 0 0.025">
                                <inertial mass="0.013" pos="0 0 0.0130769" quat="1 0 0 1"
                                  diaginertia="1.28092e-06 1.12092e-06 5.3e-07" />
                                <joint name="rh_MFJ1" class="middle_distal" />
                                <geom class="plastic_visual" mesh="f_distal_pst" />
                                <geom class="plastic_collision" type="mesh" mesh="f_distal_pst" />
                              </body>
                            </body>
                          </body>
                        </body>
                        <body name="rh_rfknuckle" pos="-0.011 0 0.095">
                          <inertial mass="0.008" pos="0 0 0" quat="0.5 0.5 -0.5 0.5"
                            diaginertia="3.2e-07 2.6e-07 2.6e-07" />
                          <joint name="rh_RFJ4" class="knuckle" axis="0 1 0" />
                          <geom pos="0 0 0.0005" class="plastic_visual" mesh="f_knuckle" material="metallic" />
                          <geom size="0.009 0.009" quat="1 0 1 0" type="cylinder" class="plastic_collision" />
                          <body name="rh_rfproximal">
                            <inertial mass="0.03" pos="0 0 0.0225" quat="1 0 0 1"
                              diaginertia="1e-05 9.8e-06 1.8e-06" />
                            <joint name="rh_RFJ3" class="proximal" />
                            <geom class="plastic_visual" mesh="f_proximal" />
                            <geom size="0.009 0.02" pos="0 0 0.025" type="capsule" class="plastic_collision" />
                            <body name="rh_rfmiddle" pos="0 0 0.045">
                              <inertial mass="0.017" pos="0 0 0.0125" quat="1 0 0 1"
                                diaginertia="2.7e-06 2.6e-06 8.7e-07" />
                              <joint name="rh_RFJ2" class="middle_distal" />
                              <geom class="plastic_visual" mesh="f_middle" />
                              <geom size="0.009 0.0125" pos="0 0 0.0125" type="capsule"
                                class="plastic_collision" />
                              <body name="rh_rfdistal" pos="0 0 0.025">
                                <inertial mass="0.013" pos="0 0 0.0130769" quat="1 0 0 1"
                                  diaginertia="1.28092e-06 1.12092e-06 5.3e-07" />
                                <joint name="rh_RFJ1" class="middle_distal" />
                                <geom class="plastic_visual" mesh="f_distal_pst" />
                                <geom class="plastic_collision" type="mesh" mesh="f_distal_pst" />
                              </body>
                            </body>
                          </body>
                        </body>
                        <body name="rh_lfmetacarpal" pos="-0.033 0 0.02071">
                          <inertial mass="0.03" pos="0 0 0.04" quat="1 0 0 1"
                            diaginertia="1.638e-05 1.45e-05 4.272e-06" />
                          <joint name="rh_LFJ5" class="metacarpal" />
                          <geom class="plastic_visual" mesh="lf_metacarpal" />
                          <geom size="0.011 0.012 0.025" pos="0.002 0 0.033" type="box"
                            class="plastic_collision" />
                          <body name="rh_lfknuckle" pos="0 0 0.06579">
                            <inertial mass="0.008" pos="0 0 0" quat="0.5 0.5 -0.5 0.5"
                              diaginertia="3.2e-07 2.6e-07 2.6e-07" />
                            <joint name="rh_LFJ4" class="knuckle" axis="0 1 0" />
                            <geom pos="0 0 0.0005" class="plastic_visual" mesh="f_knuckle" material="metallic" />
                            <geom size="0.009 0.009" quat="1 0 1 0" type="cylinder" class="plastic_collision" />
                            <body name="rh_lfproximal">
                              <inertial mass="0.03" pos="0 0 0.0225" quat="1 0 0 1"
                                diaginertia="1e-05 9.8e-06 1.8e-06" />
                              <joint name="rh_LFJ3" class="proximal" />
                              <geom class="plastic_visual" mesh="f_proximal" />
                              <geom size="0.009 0.02" pos="0 0 0.025" type="capsule" class="plastic_collision" />
                              <body name="rh_lfmiddle" pos="0 0 0.045">
                                <inertial mass="0.017" pos="0 0 0.0125" quat="1 0 0 1"
                                  diaginertia="2.7e-06 2.6e-06 8.7e-07" />
                                <joint name="rh_LFJ2" class="middle_distal" />
                                <geom class="plastic_visual" mesh="f_middle" />
                                <geom size="0.009 0.0125" pos="0 0 0.0125" type="capsule"
                                  class="plastic_collision" />
                                <body name="rh_lfdistal" pos="0 0 0.025">
                                  <inertial mass="0.013" pos="0 0 0.0130769" quat="1 0 0 1"
                                    diaginertia="1.28092e-06 1.12092e-06 5.3e-07" />
                                  <joint name="rh_LFJ1" class="middle_distal" />
                                  <geom class="plastic_visual" mesh="f_distal_pst" />
                                  <geom class="plastic_collision" type="mesh" mesh="f_distal_pst" />
                                </body>
                              </body>
                            </body>
                          </body>
                        </body>
                        <body name="rh_thbase" pos="0.034 -0.00858 0.029" quat="0.92388 0 0.382683 0">
                          <inertial mass="0.01" pos="0 0 0" diaginertia="1.6e-07 1.6e-07 1.6e-07" />
                          <joint name="rh_THJ5" class="thbase" />
                          <geom class="plastic_collision" size="0.013" />
                          <body name="rh_thproximal">
                            <inertial mass="0.04" pos="0 0 0.019" diaginertia="1.36e-05 1.36e-05 3.13e-06" />
                            <joint name="rh_THJ4" class="thproximal" />
                            <geom class="plastic_visual" mesh="th_proximal" />
                            <geom class="plastic_collision" size="0.0105 0.009" pos="0 0 0.02" type="capsule" />
                            <body name="rh_thhub" pos="0 0 0.038">
                              <inertial mass="0.005" pos="0 0 0" diaginertia="1e-06 1e-06 3e-07" />
                              <joint name="rh_THJ3" class="thhub" />
                              <geom size="0.011" class="plastic_collision" />
                              <body name="rh_thmiddle">
                                <inertial mass="0.02" pos="0 0 0.016" diaginertia="5.1e-06 5.1e-06 1.21e-06" />
                                <joint name="rh_THJ2" class="thmiddle" />
                                <geom class="plastic_visual" mesh="th_middle" />
                                <geom size="0.009 0.009" pos="0 0 0.012" type="capsule"
                                  class="plastic_collision" />
                                <geom size="0.01" pos="0 0 0.03" class="plastic_collision" />
                                <body name="rh_thdistal" pos="0 0 0.032" quat="1 0 0 -1">
                                  <inertial mass="0.017" pos="0 0 0.0145588" quat="1 0 0 1"
                                    diaginertia="2.37794e-06 2.27794e-06 1e-06" />
                                  <joint name="rh_THJ1" class="thdistal" />
                                  <geom class="plastic_visual" mesh="th_distal_pst" />
                                  <geom class="plastic_collision" type="mesh" mesh="th_distal_pst" />
                                </body>
                              </body>
                            </body>
                          </body>
                        </body>
                      </body>
                    </body>
                  </body>
                </body>
              </body>
            </body>
          </body>
        </body>
      </body>
    </body>
  </worldbody>

  <contact>
    <exclude body1="rh_wrist" body2="rh_forearm" />
    <exclude body1="rh_thproximal" body2="rh_thmiddle" />
  </contact>

  <tendon>
    <fixed name="rh_FFJ0">
      <joint joint="rh_FFJ2" coef="1" />
      <joint joint="rh_FFJ1" coef="1" />
    </fixed>
    <fixed name="rh_MFJ0">
      <joint joint="rh_MFJ2" coef="1" />
      <joint joint="rh_MFJ1" coef="1" />
    </fixed>
    <fixed name="rh_RFJ0">
      <joint joint="rh_RFJ2" coef="1" />
      <joint joint="rh_RFJ1" coef="1" />
    </fixed>
    <fixed name="rh_LFJ0">
      <joint joint="rh_LFJ2" coef="1" />
      <joint joint="rh_LFJ1" coef="1" />
    </fixed>
  </tendon>

  <actuator>
    <position class="size3" name="shoulder_pan" joint="shoulder_pan_joint" />
    <position class="size3" name="shoulder_lift" joint="shoulder_lift_joint" />
    <position class="size3_limited" name="elbow" joint="elbow_joint" />
    <position class="size1" name="wrist_1" joint="wrist_1_joint" />
    <position class="size1" name="wrist_2" joint="wrist_2_joint" />
    <position class="size1" name="wrist_3" joint="wrist_3_joint" />

    <!-- Shadow Hand -->
    <position name="rh_A_WRJ2" joint="rh_WRJ2" class="wrist_y" />
    <position name="rh_A_WRJ1" joint="rh_WRJ1" class="wrist_x" />
    <position name="rh_A_THJ5" joint="rh_THJ5" class="thbase" />
    <position name="rh_A_THJ4" joint="rh_THJ4" class="thproximal" />
    <position name="rh_A_THJ3" joint="rh_THJ3" class="thhub" />
    <position name="rh_A_THJ2" joint="rh_THJ2" class="thmiddle" />
    <position name="rh_A_THJ1" joint="rh_THJ1" class="thdistal" />
    <position name="rh_A_FFJ4" joint="rh_FFJ4" class="knuckle" />
    <position name="rh_A_FFJ3" joint="rh_FFJ3" class="proximal" />
    <position name="rh_A_FFJ0" tendon="rh_FFJ0" class="middle_distal" />
    <position name="rh_A_MFJ4" joint="rh_MFJ4" class="knuckle" />
    <position name="rh_A_MFJ3" joint="rh_MFJ3" class="proximal" />
    <position name="rh_A_MFJ0" tendon="rh_MFJ0" class="middle_distal" />
    <position name="rh_A_RFJ4" joint="rh_RFJ4" class="knuckle" />
    <position name="rh_A_RFJ3" joint="rh_RFJ3" class="proximal" />
    <position name="rh_A_RFJ0" tendon="rh_RFJ0" class="middle_distal" />
    <position name="rh_A_LFJ5" joint="rh_LFJ5" class="metacarpal" />
    <position name="rh_A_LFJ4" joint="rh_LFJ4" class="knuckle" />
    <position name="rh_A_LFJ3" joint="rh_LFJ3" class="proximal" />
    <position name="rh_A_LFJ0" tendon="rh_LFJ0" class="middle_distal" />
  </actuator>

  <keyframe>
    <key name="home" qpos="-1.5708 -1.5708 1.5708 -1.5708 -1.5708 0 0 0 0 0 0 0 0 0 0 0 0 0 0 0 0 0 0 0 0 0 0 0 0 0"
      ctrl="-1.5708 -1.5708 1.5708 -1.5708 -1.5708 0 0 0 0 0 0 0 0 0 0 0 0 0 0 0 0 0 0 0 0 0" />
  </keyframe>
</mujoco>